2020-04-27 03:47:10,005 INFO org.apache.hadoop.yarn.server.resourcemanager.ResourceManager: STARTUP_MSG: 
/************************************************************
STARTUP_MSG: Starting ResourceManager
STARTUP_MSG:   host = shivansh18-VirtualBox/127.0.1.1
STARTUP_MSG:   args = []
STARTUP_MSG:   version = 2.6.1
STARTUP_MSG:   build = https://git-wip-us.apache.org/repos/asf/hadoop.git -r b4d876d837b830405ccdb6af94742f99d49f9c04; compiled by 'jenkins' on 2015-09-16T21:07Z
STARTUP_MSG:   java = 1.8.0_252
************************************************************/
2020-04-27 03:47:10,033 INFO org.apache.hadoop.yarn.server.resourcemanager.ResourceManager: registered UNIX signal handlers for [TERM, HUP, INT]
2020-04-27 03:47:10,473 INFO org.apache.hadoop.conf.Configuration: found resource core-site.xml at file:/home/shivansh18/python-kafka-streaming-twitter-master/deploy/yarn/etc/hadoop/core-site.xml
2020-04-27 03:47:10,574 INFO org.apache.hadoop.security.Groups: clearing userToGroupsMap cache
2020-04-27 03:47:10,663 INFO org.apache.hadoop.conf.Configuration: found resource yarn-site.xml at file:/home/shivansh18/python-kafka-streaming-twitter-master/deploy/yarn/etc/hadoop/yarn-site.xml
2020-04-27 03:47:11,132 INFO org.apache.hadoop.yarn.event.AsyncDispatcher: Registering class org.apache.hadoop.yarn.server.resourcemanager.RMFatalEventType for class org.apache.hadoop.yarn.server.resourcemanager.ResourceManager$RMFatalEventDispatcher
2020-04-27 03:47:11,222 INFO org.apache.hadoop.yarn.server.resourcemanager.security.NMTokenSecretManagerInRM: NMTokenKeyRollingInterval: 86400000ms and NMTokenKeyActivationDelay: 900000ms
2020-04-27 03:47:11,230 INFO org.apache.hadoop.yarn.server.resourcemanager.security.RMContainerTokenSecretManager: ContainerTokenKeyRollingInterval: 86400000ms and ContainerTokenKeyActivationDelay: 900000ms
2020-04-27 03:47:11,236 INFO org.apache.hadoop.yarn.server.resourcemanager.security.AMRMTokenSecretManager: AMRMTokenKeyRollingInterval: 86400000ms and AMRMTokenKeyActivationDelay: 900000 ms
2020-04-27 03:47:11,271 INFO org.apache.hadoop.yarn.event.AsyncDispatcher: Registering class org.apache.hadoop.yarn.server.resourcemanager.recovery.RMStateStoreEventType for class org.apache.hadoop.yarn.server.resourcemanager.recovery.RMStateStore$ForwardingEventHandler
2020-04-27 03:47:11,273 INFO org.apache.hadoop.yarn.event.AsyncDispatcher: Registering class org.apache.hadoop.yarn.server.resourcemanager.NodesListManagerEventType for class org.apache.hadoop.yarn.server.resourcemanager.NodesListManager
2020-04-27 03:47:11,273 INFO org.apache.hadoop.yarn.server.resourcemanager.ResourceManager: Using Scheduler: org.apache.hadoop.yarn.server.resourcemanager.scheduler.capacity.CapacityScheduler
2020-04-27 03:47:11,296 INFO org.apache.hadoop.yarn.event.AsyncDispatcher: Registering class org.apache.hadoop.yarn.server.resourcemanager.scheduler.event.SchedulerEventType for class org.apache.hadoop.yarn.server.resourcemanager.ResourceManager$SchedulerEventDispatcher
2020-04-27 03:47:11,298 INFO org.apache.hadoop.yarn.event.AsyncDispatcher: Registering class org.apache.hadoop.yarn.server.resourcemanager.rmapp.RMAppEventType for class org.apache.hadoop.yarn.server.resourcemanager.ResourceManager$ApplicationEventDispatcher
2020-04-27 03:47:11,299 INFO org.apache.hadoop.yarn.event.AsyncDispatcher: Registering class org.apache.hadoop.yarn.server.resourcemanager.rmapp.attempt.RMAppAttemptEventType for class org.apache.hadoop.yarn.server.resourcemanager.ResourceManager$ApplicationAttemptEventDispatcher
2020-04-27 03:47:11,300 INFO org.apache.hadoop.yarn.event.AsyncDispatcher: Registering class org.apache.hadoop.yarn.server.resourcemanager.rmnode.RMNodeEventType for class org.apache.hadoop.yarn.server.resourcemanager.ResourceManager$NodeEventDispatcher
2020-04-27 03:47:11,388 INFO org.apache.hadoop.metrics2.impl.MetricsConfig: loaded properties from hadoop-metrics2.properties
2020-04-27 03:47:11,522 INFO org.apache.hadoop.metrics2.impl.MetricsSystemImpl: Scheduled snapshot period at 10 second(s).
2020-04-27 03:47:11,522 INFO org.apache.hadoop.metrics2.impl.MetricsSystemImpl: ResourceManager metrics system started
2020-04-27 03:47:11,541 INFO org.apache.hadoop.yarn.event.AsyncDispatcher: Registering class org.apache.hadoop.yarn.server.resourcemanager.RMAppManagerEventType for class org.apache.hadoop.yarn.server.resourcemanager.RMAppManager
2020-04-27 03:47:11,549 INFO org.apache.hadoop.yarn.event.AsyncDispatcher: Registering class org.apache.hadoop.yarn.server.resourcemanager.amlauncher.AMLauncherEventType for class org.apache.hadoop.yarn.server.resourcemanager.amlauncher.ApplicationMasterLauncher
2020-04-27 03:47:11,552 INFO org.apache.hadoop.yarn.server.resourcemanager.RMNMInfo: Registered RMNMInfo MBean
2020-04-27 03:47:11,554 INFO org.apache.hadoop.util.HostsFileReader: Refreshing hosts (include/exclude) list
2020-04-27 03:47:11,558 INFO org.apache.hadoop.conf.Configuration: found resource capacity-scheduler.xml at file:/home/shivansh18/python-kafka-streaming-twitter-master/deploy/yarn/etc/hadoop/capacity-scheduler.xml
2020-04-27 03:47:11,626 INFO org.apache.hadoop.yarn.server.resourcemanager.scheduler.capacity.ParentQueue: root, capacity=1.0, asboluteCapacity=1.0, maxCapacity=1.0, asboluteMaxCapacity=1.0, state=RUNNING, acls=ADMINISTER_QUEUE:*SUBMIT_APPLICATIONS:*, labels=*,
, reservationsContinueLooking=true
2020-04-27 03:47:11,626 INFO org.apache.hadoop.yarn.server.resourcemanager.scheduler.capacity.ParentQueue: Initialized parent-queue root name=root, fullname=root
2020-04-27 03:47:11,639 INFO org.apache.hadoop.yarn.server.resourcemanager.scheduler.capacity.LeafQueue: Initializing default
capacity = 1.0 [= (float) configuredCapacity / 100 ]
asboluteCapacity = 1.0 [= parentAbsoluteCapacity * capacity ]
maxCapacity = 1.0 [= configuredMaxCapacity ]
absoluteMaxCapacity = 1.0 [= 1.0 maximumCapacity undefined, (parentAbsoluteMaxCapacity * maximumCapacity) / 100 otherwise ]
userLimit = 100 [= configuredUserLimit ]
userLimitFactor = 1.0 [= configuredUserLimitFactor ]
maxApplications = 10000 [= configuredMaximumSystemApplicationsPerQueue or (int)(configuredMaximumSystemApplications * absoluteCapacity)]
maxApplicationsPerUser = 10000 [= (int)(maxApplications * (userLimit / 100.0f) * userLimitFactor) ]
usedCapacity = 0.0 [= usedResourcesMemory / (clusterResourceMemory * absoluteCapacity)]
absoluteUsedCapacity = 0.0 [= usedResourcesMemory / clusterResourceMemory]
maxAMResourcePerQueuePercent = 0.1 [= configuredMaximumAMResourcePercent ]
minimumAllocationFactor = 0.875 [= (float)(maximumAllocationMemory - minimumAllocationMemory) / maximumAllocationMemory ]
numContainers = 0 [= currentNumContainers ]
state = RUNNING [= configuredState ]
acls = ADMINISTER_QUEUE:*SUBMIT_APPLICATIONS:* [= configuredAcls ]
nodeLocalityDelay = 40
labels=*,
nodeLocalityDelay = 40
reservationsContinueLooking = true

2020-04-27 03:47:11,639 INFO org.apache.hadoop.yarn.server.resourcemanager.scheduler.capacity.CapacityScheduler: Initialized queue: default: capacity=1.0, absoluteCapacity=1.0, usedResources=<memory:0, vCores:0>, usedCapacity=0.0, absoluteUsedCapacity=0.0, numApps=0, numContainers=0
2020-04-27 03:47:11,640 INFO org.apache.hadoop.yarn.server.resourcemanager.scheduler.capacity.CapacityScheduler: Initialized queue: root: numChildQueue= 1, capacity=1.0, absoluteCapacity=1.0, usedResources=<memory:0, vCores:0>usedCapacity=0.0, numApps=0, numContainers=0
2020-04-27 03:47:11,641 INFO org.apache.hadoop.yarn.server.resourcemanager.scheduler.capacity.CapacityScheduler: Initialized root queue root: numChildQueue= 1, capacity=1.0, absoluteCapacity=1.0, usedResources=<memory:0, vCores:0>usedCapacity=0.0, numApps=0, numContainers=0
2020-04-27 03:47:11,641 INFO org.apache.hadoop.yarn.server.resourcemanager.scheduler.capacity.CapacityScheduler: Initialized queue mappings, override: false
2020-04-27 03:47:11,642 INFO org.apache.hadoop.yarn.server.resourcemanager.scheduler.capacity.CapacityScheduler: Initialized CapacityScheduler with calculator=class org.apache.hadoop.yarn.util.resource.DefaultResourceCalculator, minimumAllocation=<<memory:1024, vCores:1>>, maximumAllocation=<<memory:8192, vCores:32>>, asynchronousScheduling=false, asyncScheduleInterval=5ms
2020-04-27 03:47:11,652 INFO org.apache.hadoop.yarn.server.resourcemanager.metrics.SystemMetricsPublisher: YARN system metrics publishing service is not enabled
2020-04-27 03:47:11,652 INFO org.apache.hadoop.yarn.server.resourcemanager.ResourceManager: Transitioning to active state
2020-04-27 03:47:11,720 INFO org.apache.hadoop.yarn.server.resourcemanager.security.RMContainerTokenSecretManager: Rolling master-key for container-tokens
2020-04-27 03:47:11,721 INFO org.apache.hadoop.yarn.server.resourcemanager.security.NMTokenSecretManagerInRM: Rolling master-key for nm-tokens
2020-04-27 03:47:11,721 INFO org.apache.hadoop.security.token.delegation.AbstractDelegationTokenSecretManager: Updating the current master key for generating delegation tokens
2020-04-27 03:47:11,722 INFO org.apache.hadoop.yarn.server.resourcemanager.security.RMDelegationTokenSecretManager: storing master key with keyID 1
2020-04-27 03:47:11,723 INFO org.apache.hadoop.security.token.delegation.AbstractDelegationTokenSecretManager: Starting expired delegation token remover thread, tokenRemoverScanInterval=60 min(s)
2020-04-27 03:47:11,723 INFO org.apache.hadoop.security.token.delegation.AbstractDelegationTokenSecretManager: Updating the current master key for generating delegation tokens
2020-04-27 03:47:11,724 INFO org.apache.hadoop.yarn.server.resourcemanager.security.RMDelegationTokenSecretManager: storing master key with keyID 2
2020-04-27 03:47:11,754 INFO org.apache.hadoop.ipc.CallQueueManager: Using callQueue class java.util.concurrent.LinkedBlockingQueue
2020-04-27 03:47:11,773 INFO org.apache.hadoop.ipc.Server: Starting Socket Reader #1 for port 8031
2020-04-27 03:47:11,794 INFO org.apache.hadoop.yarn.factories.impl.pb.RpcServerFactoryPBImpl: Adding protocol org.apache.hadoop.yarn.server.api.ResourceTrackerPB to the server
2020-04-27 03:47:11,795 INFO org.apache.hadoop.ipc.Server: IPC Server Responder: starting
2020-04-27 03:47:11,796 INFO org.apache.hadoop.ipc.Server: IPC Server listener on 8031: starting
2020-04-27 03:47:11,844 INFO org.apache.hadoop.ipc.CallQueueManager: Using callQueue class java.util.concurrent.LinkedBlockingQueue
2020-04-27 03:47:11,853 INFO org.apache.hadoop.ipc.Server: Starting Socket Reader #1 for port 8030
2020-04-27 03:47:11,867 INFO org.apache.hadoop.yarn.factories.impl.pb.RpcServerFactoryPBImpl: Adding protocol org.apache.hadoop.yarn.api.ApplicationMasterProtocolPB to the server
2020-04-27 03:47:11,867 INFO org.apache.hadoop.ipc.Server: IPC Server Responder: starting
2020-04-27 03:47:11,867 INFO org.apache.hadoop.ipc.Server: IPC Server listener on 8030: starting
2020-04-27 03:47:11,925 INFO org.apache.hadoop.ipc.CallQueueManager: Using callQueue class java.util.concurrent.LinkedBlockingQueue
2020-04-27 03:47:11,926 INFO org.apache.hadoop.ipc.Server: Starting Socket Reader #1 for port 8032
2020-04-27 03:47:11,929 INFO org.apache.hadoop.yarn.factories.impl.pb.RpcServerFactoryPBImpl: Adding protocol org.apache.hadoop.yarn.api.ApplicationClientProtocolPB to the server
2020-04-27 03:47:11,931 INFO org.apache.hadoop.ipc.Server: IPC Server Responder: starting
2020-04-27 03:47:11,931 INFO org.apache.hadoop.ipc.Server: IPC Server listener on 8032: starting
2020-04-27 03:47:11,956 INFO org.apache.hadoop.yarn.server.resourcemanager.ResourceManager: Transitioned to active state
2020-04-27 03:47:12,036 INFO org.mortbay.log: Logging to org.slf4j.impl.Log4jLoggerAdapter(org.mortbay.log) via org.mortbay.log.Slf4jLog
2020-04-27 03:47:12,041 INFO org.apache.hadoop.http.HttpRequestLog: Http request log for http.requests.resourcemanager is not defined
2020-04-27 03:47:12,057 INFO org.apache.hadoop.http.HttpServer2: Added global filter 'safety' (class=org.apache.hadoop.http.HttpServer2$QuotingInputFilter)
2020-04-27 03:47:12,068 INFO org.apache.hadoop.http.HttpServer2: Added filter RMAuthenticationFilter (class=org.apache.hadoop.yarn.server.security.http.RMAuthenticationFilter) to context cluster
2020-04-27 03:47:12,068 INFO org.apache.hadoop.http.HttpServer2: Added filter RMAuthenticationFilter (class=org.apache.hadoop.yarn.server.security.http.RMAuthenticationFilter) to context logs
2020-04-27 03:47:12,068 INFO org.apache.hadoop.http.HttpServer2: Added filter RMAuthenticationFilter (class=org.apache.hadoop.yarn.server.security.http.RMAuthenticationFilter) to context static
2020-04-27 03:47:12,069 INFO org.apache.hadoop.http.HttpServer2: Added filter static_user_filter (class=org.apache.hadoop.http.lib.StaticUserWebFilter$StaticUserFilter) to context cluster
2020-04-27 03:47:12,069 INFO org.apache.hadoop.http.HttpServer2: Added filter static_user_filter (class=org.apache.hadoop.http.lib.StaticUserWebFilter$StaticUserFilter) to context logs
2020-04-27 03:47:12,069 INFO org.apache.hadoop.http.HttpServer2: Added filter static_user_filter (class=org.apache.hadoop.http.lib.StaticUserWebFilter$StaticUserFilter) to context static
2020-04-27 03:47:12,075 INFO org.apache.hadoop.http.HttpServer2: adding path spec: /cluster/*
2020-04-27 03:47:12,075 INFO org.apache.hadoop.http.HttpServer2: adding path spec: /ws/*
2020-04-27 03:47:12,089 INFO org.apache.hadoop.http.HttpServer2: Jetty bound to port 8088
2020-04-27 03:47:12,089 INFO org.mortbay.log: jetty-6.1.26
2020-04-27 03:47:12,127 INFO org.mortbay.log: Extract jar:file:/home/shivansh18/python-kafka-streaming-twitter-master/deploy/yarn/share/hadoop/yarn/hadoop-yarn-common-2.6.1.jar!/webapps/cluster to /tmp/Jetty_0_0_0_0_8088_cluster____u0rgz3/webapp
2020-04-27 03:47:12,394 INFO org.apache.hadoop.security.token.delegation.AbstractDelegationTokenSecretManager: Updating the current master key for generating delegation tokens
2020-04-27 03:47:12,395 INFO org.apache.hadoop.security.token.delegation.AbstractDelegationTokenSecretManager: Starting expired delegation token remover thread, tokenRemoverScanInterval=60 min(s)
2020-04-27 03:47:12,395 INFO org.apache.hadoop.security.token.delegation.AbstractDelegationTokenSecretManager: Updating the current master key for generating delegation tokens
2020-04-27 03:47:12,435 INFO org.apache.hadoop.security.token.delegation.AbstractDelegationTokenSecretManager: Updating the current master key for generating delegation tokens
2020-04-27 03:47:12,436 INFO org.apache.hadoop.security.token.delegation.AbstractDelegationTokenSecretManager: Starting expired delegation token remover thread, tokenRemoverScanInterval=60 min(s)
2020-04-27 03:47:12,436 INFO org.apache.hadoop.security.token.delegation.AbstractDelegationTokenSecretManager: Updating the current master key for generating delegation tokens
2020-04-27 03:47:12,437 INFO org.apache.hadoop.security.token.delegation.AbstractDelegationTokenSecretManager: Updating the current master key for generating delegation tokens
2020-04-27 03:47:12,437 INFO org.apache.hadoop.security.token.delegation.AbstractDelegationTokenSecretManager: Starting expired delegation token remover thread, tokenRemoverScanInterval=60 min(s)
2020-04-27 03:47:12,438 INFO org.apache.hadoop.security.token.delegation.AbstractDelegationTokenSecretManager: Updating the current master key for generating delegation tokens
2020-04-27 03:47:12,444 INFO org.mortbay.log: Started HttpServer2$SelectChannelConnectorWithSafeStartup@0.0.0.0:8088
2020-04-27 03:47:12,444 INFO org.apache.hadoop.yarn.webapp.WebApps: Web app /cluster started at 8088
2020-04-27 03:47:13,162 INFO org.apache.hadoop.yarn.webapp.WebApps: Registered webapp guice modules
2020-04-27 03:47:13,192 INFO org.apache.hadoop.ipc.CallQueueManager: Using callQueue class java.util.concurrent.LinkedBlockingQueue
2020-04-27 03:47:13,193 INFO org.apache.hadoop.ipc.Server: Starting Socket Reader #1 for port 8033
2020-04-27 03:47:13,195 INFO org.apache.hadoop.yarn.factories.impl.pb.RpcServerFactoryPBImpl: Adding protocol org.apache.hadoop.yarn.server.api.ResourceManagerAdministrationProtocolPB to the server
2020-04-27 03:47:13,199 INFO org.apache.hadoop.ipc.Server: IPC Server listener on 8033: starting
2020-04-27 03:47:13,199 INFO org.apache.hadoop.ipc.Server: IPC Server Responder: starting
2020-04-27 03:47:16,467 INFO org.apache.hadoop.yarn.util.RackResolver: Resolved shivansh18-VirtualBox to /default-rack
2020-04-27 03:47:16,470 INFO org.apache.hadoop.yarn.server.resourcemanager.ResourceTrackerService: NodeManager from node shivansh18-VirtualBox(cmPort: 45511 httpPort: 8042) registered with capability: <memory:8192, vCores:8>, assigned nodeId shivansh18-VirtualBox:45511
2020-04-27 03:47:16,472 INFO org.apache.hadoop.yarn.server.resourcemanager.rmnode.RMNodeImpl: shivansh18-VirtualBox:45511 Node Transitioned from NEW to RUNNING
2020-04-27 03:47:16,474 INFO org.apache.hadoop.yarn.server.resourcemanager.scheduler.capacity.CapacityScheduler: Added node shivansh18-VirtualBox:45511 clusterResource: <memory:8192, vCores:8>
2020-04-27 03:57:11,644 INFO org.apache.hadoop.yarn.server.resourcemanager.scheduler.AbstractYarnScheduler: Release request cache is cleaned up
2020-04-27 04:53:14,382 INFO org.apache.hadoop.yarn.server.resourcemanager.ClientRMService: Allocated new applicationId: 1
2020-04-27 05:01:43,944 INFO org.apache.hadoop.yarn.server.resourcemanager.ClientRMService: Allocated new applicationId: 2
2020-04-27 05:01:44,752 WARN org.apache.hadoop.yarn.server.resourcemanager.rmapp.RMAppImpl: The specific max attempts: 0 for application: 2 is invalid, because it is out of the range [1, 2]. Use the global max attempts instead.
2020-04-27 05:01:44,753 INFO org.apache.hadoop.yarn.server.resourcemanager.ClientRMService: Application with id 2 submitted by user root
2020-04-27 05:01:44,758 INFO org.apache.hadoop.yarn.server.resourcemanager.rmapp.RMAppImpl: Storing application with id application_1587939431661_0002
2020-04-27 05:01:44,777 INFO org.apache.hadoop.yarn.server.resourcemanager.RMAuditLogger: USER=root	IP=127.0.0.1	OPERATION=Submit Application Request	TARGET=ClientRMService	RESULT=SUCCESS	APPID=application_1587939431661_0002
2020-04-27 05:01:44,851 INFO org.apache.hadoop.yarn.server.resourcemanager.rmapp.RMAppImpl: application_1587939431661_0002 State change from NEW to NEW_SAVING
2020-04-27 05:01:44,876 INFO org.apache.hadoop.yarn.server.resourcemanager.recovery.RMStateStore: Storing info for app: application_1587939431661_0002
2020-04-27 05:01:44,947 INFO org.apache.hadoop.yarn.server.resourcemanager.rmapp.RMAppImpl: application_1587939431661_0002 State change from NEW_SAVING to SUBMITTED
2020-04-27 05:01:44,967 INFO org.apache.hadoop.yarn.server.resourcemanager.scheduler.capacity.ParentQueue: Application added - appId: application_1587939431661_0002 user: root leaf-queue of parent: root #applications: 1
2020-04-27 05:01:44,968 INFO org.apache.hadoop.yarn.server.resourcemanager.scheduler.capacity.CapacityScheduler: Accepted application application_1587939431661_0002 from user: root, in queue: default
2020-04-27 05:01:44,972 INFO org.apache.hadoop.yarn.server.resourcemanager.rmapp.RMAppImpl: application_1587939431661_0002 State change from SUBMITTED to ACCEPTED
2020-04-27 05:01:45,075 INFO org.apache.hadoop.yarn.server.resourcemanager.ApplicationMasterService: Registering app attempt : appattempt_1587939431661_0002_000001
2020-04-27 05:01:45,077 INFO org.apache.hadoop.yarn.server.resourcemanager.rmapp.attempt.RMAppAttemptImpl: appattempt_1587939431661_0002_000001 State change from NEW to SUBMITTED
2020-04-27 05:01:45,141 INFO org.apache.hadoop.yarn.server.resourcemanager.scheduler.capacity.LeafQueue: Application application_1587939431661_0002 from user: root activated in queue: default
2020-04-27 05:01:45,141 INFO org.apache.hadoop.yarn.server.resourcemanager.scheduler.capacity.LeafQueue: Application added - appId: application_1587939431661_0002 user: org.apache.hadoop.yarn.server.resourcemanager.scheduler.capacity.LeafQueue$User@3adc142e, leaf-queue: default #user-pending-applications: 0 #user-active-applications: 1 #queue-pending-applications: 0 #queue-active-applications: 1
2020-04-27 05:01:45,142 INFO org.apache.hadoop.yarn.server.resourcemanager.scheduler.capacity.CapacityScheduler: Added Application Attempt appattempt_1587939431661_0002_000001 to scheduler from user root in queue default
2020-04-27 05:01:45,146 INFO org.apache.hadoop.yarn.server.resourcemanager.rmapp.attempt.RMAppAttemptImpl: appattempt_1587939431661_0002_000001 State change from SUBMITTED to SCHEDULED
2020-04-27 05:01:45,877 INFO org.apache.hadoop.yarn.server.resourcemanager.rmcontainer.RMContainerImpl: container_1587939431661_0002_01_000001 Container Transitioned from NEW to ALLOCATED
2020-04-27 05:01:45,879 INFO org.apache.hadoop.yarn.server.resourcemanager.RMAuditLogger: USER=root	OPERATION=AM Allocated Container	TARGET=SchedulerApp	RESULT=SUCCESS	APPID=application_1587939431661_0002	CONTAINERID=container_1587939431661_0002_01_000001
2020-04-27 05:01:45,882 INFO org.apache.hadoop.yarn.server.resourcemanager.scheduler.SchedulerNode: Assigned container container_1587939431661_0002_01_000001 of capacity <memory:1024, vCores:1> on host shivansh18-VirtualBox:45511, which has 1 containers, <memory:1024, vCores:1> used and <memory:7168, vCores:7> available after allocation
2020-04-27 05:01:45,882 INFO org.apache.hadoop.yarn.server.resourcemanager.scheduler.capacity.LeafQueue: assignedContainer application attempt=appattempt_1587939431661_0002_000001 container=Container: [ContainerId: container_1587939431661_0002_01_000001, NodeId: shivansh18-VirtualBox:45511, NodeHttpAddress: shivansh18-VirtualBox:8042, Resource: <memory:1024, vCores:1>, Priority: 0, Token: null, ] queue=default: capacity=1.0, absoluteCapacity=1.0, usedResources=<memory:0, vCores:0>, usedCapacity=0.0, absoluteUsedCapacity=0.0, numApps=1, numContainers=0 clusterResource=<memory:8192, vCores:8>
2020-04-27 05:01:45,884 INFO org.apache.hadoop.yarn.server.resourcemanager.scheduler.capacity.ParentQueue: Re-sorting assigned queue: root.default stats: default: capacity=1.0, absoluteCapacity=1.0, usedResources=<memory:1024, vCores:1>, usedCapacity=0.125, absoluteUsedCapacity=0.125, numApps=1, numContainers=1
2020-04-27 05:01:45,884 INFO org.apache.hadoop.yarn.server.resourcemanager.scheduler.capacity.ParentQueue: assignedContainer queue=root usedCapacity=0.125 absoluteUsedCapacity=0.125 used=<memory:1024, vCores:1> cluster=<memory:8192, vCores:8>
2020-04-27 05:01:46,008 INFO org.apache.hadoop.yarn.server.resourcemanager.security.NMTokenSecretManagerInRM: Sending NMToken for nodeId : shivansh18-VirtualBox:45511 for container : container_1587939431661_0002_01_000001
2020-04-27 05:01:46,031 INFO org.apache.hadoop.yarn.server.resourcemanager.rmcontainer.RMContainerImpl: container_1587939431661_0002_01_000001 Container Transitioned from ALLOCATED to ACQUIRED
2020-04-27 05:01:46,032 INFO org.apache.hadoop.yarn.server.resourcemanager.security.NMTokenSecretManagerInRM: Clear node set for appattempt_1587939431661_0002_000001
2020-04-27 05:01:46,033 INFO org.apache.hadoop.yarn.server.resourcemanager.rmapp.attempt.RMAppAttemptImpl: Storing attempt: AppId: application_1587939431661_0002 AttemptId: appattempt_1587939431661_0002_000001 MasterContainer: Container: [ContainerId: container_1587939431661_0002_01_000001, NodeId: shivansh18-VirtualBox:45511, NodeHttpAddress: shivansh18-VirtualBox:8042, Resource: <memory:1024, vCores:1>, Priority: 0, Token: Token { kind: ContainerToken, service: 127.0.1.1:45511 }, ]
2020-04-27 05:01:46,079 INFO org.apache.hadoop.yarn.server.resourcemanager.rmapp.attempt.RMAppAttemptImpl: appattempt_1587939431661_0002_000001 State change from SCHEDULED to ALLOCATED_SAVING
2020-04-27 05:01:46,099 INFO org.apache.hadoop.yarn.server.resourcemanager.rmapp.attempt.RMAppAttemptImpl: appattempt_1587939431661_0002_000001 State change from ALLOCATED_SAVING to ALLOCATED
2020-04-27 05:01:46,105 INFO org.apache.hadoop.yarn.server.resourcemanager.amlauncher.AMLauncher: Launching masterappattempt_1587939431661_0002_000001
2020-04-27 05:01:46,216 INFO org.apache.hadoop.yarn.server.resourcemanager.amlauncher.AMLauncher: Setting up container Container: [ContainerId: container_1587939431661_0002_01_000001, NodeId: shivansh18-VirtualBox:45511, NodeHttpAddress: shivansh18-VirtualBox:8042, Resource: <memory:1024, vCores:1>, Priority: 0, Token: Token { kind: ContainerToken, service: 127.0.1.1:45511 }, ] for AM appattempt_1587939431661_0002_000001
2020-04-27 05:01:46,216 INFO org.apache.hadoop.yarn.server.resourcemanager.amlauncher.AMLauncher: Command to launch container container_1587939431661_0002_01_000001 : export SAMZA_LOG_DIR=<LOG_DIR> && ln -sfn <LOG_DIR> logs && exec ./__package/bin/run-am.sh 1>logs/stdout 2>logs/stderr
2020-04-27 05:01:46,219 INFO org.apache.hadoop.yarn.server.resourcemanager.security.AMRMTokenSecretManager: Create AMRMToken for ApplicationAttempt: appattempt_1587939431661_0002_000001
2020-04-27 05:01:46,223 INFO org.apache.hadoop.yarn.server.resourcemanager.security.AMRMTokenSecretManager: Creating password for appattempt_1587939431661_0002_000001
2020-04-27 05:01:47,517 INFO org.apache.hadoop.yarn.server.resourcemanager.amlauncher.AMLauncher: Done launching container Container: [ContainerId: container_1587939431661_0002_01_000001, NodeId: shivansh18-VirtualBox:45511, NodeHttpAddress: shivansh18-VirtualBox:8042, Resource: <memory:1024, vCores:1>, Priority: 0, Token: Token { kind: ContainerToken, service: 127.0.1.1:45511 }, ] for AM appattempt_1587939431661_0002_000001
2020-04-27 05:01:47,518 INFO org.apache.hadoop.yarn.server.resourcemanager.rmapp.attempt.RMAppAttemptImpl: appattempt_1587939431661_0002_000001 State change from ALLOCATED to LAUNCHED
2020-04-27 05:01:47,828 INFO org.apache.hadoop.yarn.server.resourcemanager.rmcontainer.RMContainerImpl: container_1587939431661_0002_01_000001 Container Transitioned from ACQUIRED to RUNNING
2020-04-27 05:02:08,130 INFO org.apache.hadoop.yarn.server.resourcemanager.rmcontainer.RMContainerImpl: container_1587939431661_0002_01_000001 Container Transitioned from RUNNING to COMPLETED
2020-04-27 05:02:08,141 INFO org.apache.hadoop.yarn.server.resourcemanager.scheduler.common.fica.FiCaSchedulerApp: Completed container: container_1587939431661_0002_01_000001 in state: COMPLETED event:FINISHED
2020-04-27 05:02:08,141 INFO org.apache.hadoop.yarn.server.resourcemanager.RMAuditLogger: USER=root	OPERATION=AM Released Container	TARGET=SchedulerApp	RESULT=SUCCESS	APPID=application_1587939431661_0002	CONTAINERID=container_1587939431661_0002_01_000001
2020-04-27 05:02:08,141 INFO org.apache.hadoop.yarn.server.resourcemanager.scheduler.SchedulerNode: Released container container_1587939431661_0002_01_000001 of capacity <memory:1024, vCores:1> on host shivansh18-VirtualBox:45511, which currently has 0 containers, <memory:0, vCores:0> used and <memory:8192, vCores:8> available, release resources=true
2020-04-27 05:02:08,141 INFO org.apache.hadoop.yarn.server.resourcemanager.scheduler.capacity.LeafQueue: default used=<memory:0, vCores:0> numContainers=0 user=root user-resources=<memory:0, vCores:0>
2020-04-27 05:02:08,142 INFO org.apache.hadoop.yarn.server.resourcemanager.scheduler.capacity.LeafQueue: completedContainer container=Container: [ContainerId: container_1587939431661_0002_01_000001, NodeId: shivansh18-VirtualBox:45511, NodeHttpAddress: shivansh18-VirtualBox:8042, Resource: <memory:1024, vCores:1>, Priority: 0, Token: Token { kind: ContainerToken, service: 127.0.1.1:45511 }, ] queue=default: capacity=1.0, absoluteCapacity=1.0, usedResources=<memory:0, vCores:0>, usedCapacity=0.0, absoluteUsedCapacity=0.0, numApps=1, numContainers=0 cluster=<memory:8192, vCores:8>
2020-04-27 05:02:08,142 INFO org.apache.hadoop.yarn.server.resourcemanager.scheduler.capacity.ParentQueue: completedContainer queue=root usedCapacity=0.0 absoluteUsedCapacity=0.0 used=<memory:0, vCores:0> cluster=<memory:8192, vCores:8>
2020-04-27 05:02:08,142 INFO org.apache.hadoop.yarn.server.resourcemanager.scheduler.capacity.ParentQueue: Re-sorting completed queue: root.default stats: default: capacity=1.0, absoluteCapacity=1.0, usedResources=<memory:0, vCores:0>, usedCapacity=0.0, absoluteUsedCapacity=0.0, numApps=1, numContainers=0
2020-04-27 05:02:08,142 INFO org.apache.hadoop.yarn.server.resourcemanager.scheduler.capacity.CapacityScheduler: Application attempt appattempt_1587939431661_0002_000001 released container container_1587939431661_0002_01_000001 on node: host: shivansh18-VirtualBox:45511 #containers=0 available=8192 used=0 with event: FINISHED
2020-04-27 05:02:08,165 INFO org.apache.hadoop.yarn.server.resourcemanager.rmapp.attempt.RMAppAttemptImpl: Updating application attempt appattempt_1587939431661_0002_000001 with final state: FAILED, and exit status: -103
2020-04-27 05:02:08,184 INFO org.apache.hadoop.yarn.server.resourcemanager.rmapp.attempt.RMAppAttemptImpl: appattempt_1587939431661_0002_000001 State change from LAUNCHED to FINAL_SAVING
2020-04-27 05:02:08,185 INFO org.apache.hadoop.yarn.server.resourcemanager.ApplicationMasterService: Unregistering app attempt : appattempt_1587939431661_0002_000001
2020-04-27 05:02:08,190 INFO org.apache.hadoop.yarn.server.resourcemanager.security.AMRMTokenSecretManager: Application finished, removing password for appattempt_1587939431661_0002_000001
2020-04-27 05:02:08,190 INFO org.apache.hadoop.yarn.server.resourcemanager.rmapp.attempt.RMAppAttemptImpl: appattempt_1587939431661_0002_000001 State change from FINAL_SAVING to FAILED
2020-04-27 05:02:08,190 INFO org.apache.hadoop.yarn.server.resourcemanager.rmapp.RMAppImpl: The number of failed attempts is 1. The max attempts is 2
2020-04-27 05:02:08,191 INFO org.apache.hadoop.yarn.server.resourcemanager.ApplicationMasterService: Registering app attempt : appattempt_1587939431661_0002_000002
2020-04-27 05:02:08,191 INFO org.apache.hadoop.yarn.server.resourcemanager.rmapp.attempt.RMAppAttemptImpl: appattempt_1587939431661_0002_000002 State change from NEW to SUBMITTED
2020-04-27 05:02:08,192 INFO org.apache.hadoop.yarn.server.resourcemanager.scheduler.capacity.CapacityScheduler: Application Attempt appattempt_1587939431661_0002_000001 is done. finalState=FAILED
2020-04-27 05:02:08,192 INFO org.apache.hadoop.yarn.server.resourcemanager.scheduler.AppSchedulingInfo: Application application_1587939431661_0002 requests cleared
2020-04-27 05:02:08,193 INFO org.apache.hadoop.yarn.server.resourcemanager.scheduler.capacity.LeafQueue: Application removed - appId: application_1587939431661_0002 user: root queue: default #user-pending-applications: 0 #user-active-applications: 0 #queue-pending-applications: 0 #queue-active-applications: 0
2020-04-27 05:02:08,193 INFO org.apache.hadoop.yarn.server.resourcemanager.scheduler.capacity.LeafQueue: Application application_1587939431661_0002 from user: root activated in queue: default
2020-04-27 05:02:08,193 INFO org.apache.hadoop.yarn.server.resourcemanager.scheduler.capacity.LeafQueue: Application added - appId: application_1587939431661_0002 user: org.apache.hadoop.yarn.server.resourcemanager.scheduler.capacity.LeafQueue$User@1233861, leaf-queue: default #user-pending-applications: 0 #user-active-applications: 1 #queue-pending-applications: 0 #queue-active-applications: 1
2020-04-27 05:02:08,193 INFO org.apache.hadoop.yarn.server.resourcemanager.scheduler.capacity.CapacityScheduler: Added Application Attempt appattempt_1587939431661_0002_000002 to scheduler from user root in queue default
2020-04-27 05:02:08,194 INFO org.apache.hadoop.yarn.server.resourcemanager.rmapp.attempt.RMAppAttemptImpl: appattempt_1587939431661_0002_000002 State change from SUBMITTED to SCHEDULED
2020-04-27 05:02:09,134 INFO org.apache.hadoop.yarn.server.resourcemanager.rmcontainer.RMContainerImpl: container_1587939431661_0002_02_000001 Container Transitioned from NEW to ALLOCATED
2020-04-27 05:02:09,134 INFO org.apache.hadoop.yarn.server.resourcemanager.RMAuditLogger: USER=root	OPERATION=AM Allocated Container	TARGET=SchedulerApp	RESULT=SUCCESS	APPID=application_1587939431661_0002	CONTAINERID=container_1587939431661_0002_02_000001
2020-04-27 05:02:09,134 INFO org.apache.hadoop.yarn.server.resourcemanager.scheduler.SchedulerNode: Assigned container container_1587939431661_0002_02_000001 of capacity <memory:1024, vCores:1> on host shivansh18-VirtualBox:45511, which has 1 containers, <memory:1024, vCores:1> used and <memory:7168, vCores:7> available after allocation
2020-04-27 05:02:09,135 INFO org.apache.hadoop.yarn.server.resourcemanager.scheduler.capacity.LeafQueue: assignedContainer application attempt=appattempt_1587939431661_0002_000002 container=Container: [ContainerId: container_1587939431661_0002_02_000001, NodeId: shivansh18-VirtualBox:45511, NodeHttpAddress: shivansh18-VirtualBox:8042, Resource: <memory:1024, vCores:1>, Priority: 0, Token: null, ] queue=default: capacity=1.0, absoluteCapacity=1.0, usedResources=<memory:0, vCores:0>, usedCapacity=0.0, absoluteUsedCapacity=0.0, numApps=1, numContainers=0 clusterResource=<memory:8192, vCores:8>
2020-04-27 05:02:09,135 INFO org.apache.hadoop.yarn.server.resourcemanager.scheduler.capacity.ParentQueue: Re-sorting assigned queue: root.default stats: default: capacity=1.0, absoluteCapacity=1.0, usedResources=<memory:1024, vCores:1>, usedCapacity=0.125, absoluteUsedCapacity=0.125, numApps=1, numContainers=1
2020-04-27 05:02:09,135 INFO org.apache.hadoop.yarn.server.resourcemanager.scheduler.capacity.ParentQueue: assignedContainer queue=root usedCapacity=0.125 absoluteUsedCapacity=0.125 used=<memory:1024, vCores:1> cluster=<memory:8192, vCores:8>
2020-04-27 05:02:09,137 INFO org.apache.hadoop.yarn.server.resourcemanager.security.NMTokenSecretManagerInRM: Sending NMToken for nodeId : shivansh18-VirtualBox:45511 for container : container_1587939431661_0002_02_000001
2020-04-27 05:02:09,142 INFO org.apache.hadoop.yarn.server.resourcemanager.rmcontainer.RMContainerImpl: container_1587939431661_0002_02_000001 Container Transitioned from ALLOCATED to ACQUIRED
2020-04-27 05:02:09,142 INFO org.apache.hadoop.yarn.server.resourcemanager.security.NMTokenSecretManagerInRM: Clear node set for appattempt_1587939431661_0002_000002
2020-04-27 05:02:09,143 INFO org.apache.hadoop.yarn.server.resourcemanager.rmapp.attempt.RMAppAttemptImpl: Storing attempt: AppId: application_1587939431661_0002 AttemptId: appattempt_1587939431661_0002_000002 MasterContainer: Container: [ContainerId: container_1587939431661_0002_02_000001, NodeId: shivansh18-VirtualBox:45511, NodeHttpAddress: shivansh18-VirtualBox:8042, Resource: <memory:1024, vCores:1>, Priority: 0, Token: Token { kind: ContainerToken, service: 127.0.1.1:45511 }, ]
2020-04-27 05:02:09,143 INFO org.apache.hadoop.yarn.server.resourcemanager.rmapp.attempt.RMAppAttemptImpl: appattempt_1587939431661_0002_000002 State change from SCHEDULED to ALLOCATED_SAVING
2020-04-27 05:02:09,143 INFO org.apache.hadoop.yarn.server.resourcemanager.rmapp.attempt.RMAppAttemptImpl: appattempt_1587939431661_0002_000002 State change from ALLOCATED_SAVING to ALLOCATED
2020-04-27 05:02:09,144 INFO org.apache.hadoop.yarn.server.resourcemanager.amlauncher.AMLauncher: Launching masterappattempt_1587939431661_0002_000002
2020-04-27 05:02:09,149 INFO org.apache.hadoop.yarn.server.resourcemanager.amlauncher.AMLauncher: Setting up container Container: [ContainerId: container_1587939431661_0002_02_000001, NodeId: shivansh18-VirtualBox:45511, NodeHttpAddress: shivansh18-VirtualBox:8042, Resource: <memory:1024, vCores:1>, Priority: 0, Token: Token { kind: ContainerToken, service: 127.0.1.1:45511 }, ] for AM appattempt_1587939431661_0002_000002
2020-04-27 05:02:09,149 INFO org.apache.hadoop.yarn.server.resourcemanager.amlauncher.AMLauncher: Command to launch container container_1587939431661_0002_02_000001 : export SAMZA_LOG_DIR=<LOG_DIR> && ln -sfn <LOG_DIR> logs && exec ./__package/bin/run-am.sh 1>logs/stdout 2>logs/stderr
2020-04-27 05:02:09,150 INFO org.apache.hadoop.yarn.server.resourcemanager.security.AMRMTokenSecretManager: Create AMRMToken for ApplicationAttempt: appattempt_1587939431661_0002_000002
2020-04-27 05:02:09,150 INFO org.apache.hadoop.yarn.server.resourcemanager.security.AMRMTokenSecretManager: Creating password for appattempt_1587939431661_0002_000002
2020-04-27 05:02:09,197 INFO org.apache.hadoop.yarn.server.resourcemanager.amlauncher.AMLauncher: Done launching container Container: [ContainerId: container_1587939431661_0002_02_000001, NodeId: shivansh18-VirtualBox:45511, NodeHttpAddress: shivansh18-VirtualBox:8042, Resource: <memory:1024, vCores:1>, Priority: 0, Token: Token { kind: ContainerToken, service: 127.0.1.1:45511 }, ] for AM appattempt_1587939431661_0002_000002
2020-04-27 05:02:09,197 INFO org.apache.hadoop.yarn.server.resourcemanager.rmapp.attempt.RMAppAttemptImpl: appattempt_1587939431661_0002_000002 State change from ALLOCATED to LAUNCHED
2020-04-27 05:02:10,136 INFO org.apache.hadoop.yarn.server.resourcemanager.rmcontainer.RMContainerImpl: container_1587939431661_0002_02_000001 Container Transitioned from ACQUIRED to RUNNING
2020-04-27 05:02:14,145 INFO org.apache.hadoop.yarn.server.resourcemanager.rmcontainer.RMContainerImpl: container_1587939431661_0002_02_000001 Container Transitioned from RUNNING to COMPLETED
2020-04-27 05:02:14,145 INFO org.apache.hadoop.yarn.server.resourcemanager.scheduler.common.fica.FiCaSchedulerApp: Completed container: container_1587939431661_0002_02_000001 in state: COMPLETED event:FINISHED
2020-04-27 05:02:14,146 INFO org.apache.hadoop.yarn.server.resourcemanager.RMAuditLogger: USER=root	OPERATION=AM Released Container	TARGET=SchedulerApp	RESULT=SUCCESS	APPID=application_1587939431661_0002	CONTAINERID=container_1587939431661_0002_02_000001
2020-04-27 05:02:14,146 INFO org.apache.hadoop.yarn.server.resourcemanager.scheduler.SchedulerNode: Released container container_1587939431661_0002_02_000001 of capacity <memory:1024, vCores:1> on host shivansh18-VirtualBox:45511, which currently has 0 containers, <memory:0, vCores:0> used and <memory:8192, vCores:8> available, release resources=true
2020-04-27 05:02:14,146 INFO org.apache.hadoop.yarn.server.resourcemanager.rmapp.attempt.RMAppAttemptImpl: Updating application attempt appattempt_1587939431661_0002_000002 with final state: FAILED, and exit status: -103
2020-04-27 05:02:14,146 INFO org.apache.hadoop.yarn.server.resourcemanager.scheduler.capacity.LeafQueue: default used=<memory:0, vCores:0> numContainers=0 user=root user-resources=<memory:0, vCores:0>
2020-04-27 05:02:14,146 INFO org.apache.hadoop.yarn.server.resourcemanager.rmapp.attempt.RMAppAttemptImpl: appattempt_1587939431661_0002_000002 State change from LAUNCHED to FINAL_SAVING
2020-04-27 05:02:14,146 INFO org.apache.hadoop.yarn.server.resourcemanager.scheduler.capacity.LeafQueue: completedContainer container=Container: [ContainerId: container_1587939431661_0002_02_000001, NodeId: shivansh18-VirtualBox:45511, NodeHttpAddress: shivansh18-VirtualBox:8042, Resource: <memory:1024, vCores:1>, Priority: 0, Token: Token { kind: ContainerToken, service: 127.0.1.1:45511 }, ] queue=default: capacity=1.0, absoluteCapacity=1.0, usedResources=<memory:0, vCores:0>, usedCapacity=0.0, absoluteUsedCapacity=0.0, numApps=1, numContainers=0 cluster=<memory:8192, vCores:8>
2020-04-27 05:02:14,146 INFO org.apache.hadoop.yarn.server.resourcemanager.scheduler.capacity.ParentQueue: completedContainer queue=root usedCapacity=0.0 absoluteUsedCapacity=0.0 used=<memory:0, vCores:0> cluster=<memory:8192, vCores:8>
2020-04-27 05:02:14,146 INFO org.apache.hadoop.yarn.server.resourcemanager.ApplicationMasterService: Unregistering app attempt : appattempt_1587939431661_0002_000002
2020-04-27 05:02:14,156 INFO org.apache.hadoop.yarn.server.resourcemanager.scheduler.capacity.ParentQueue: Re-sorting completed queue: root.default stats: default: capacity=1.0, absoluteCapacity=1.0, usedResources=<memory:0, vCores:0>, usedCapacity=0.0, absoluteUsedCapacity=0.0, numApps=1, numContainers=0
2020-04-27 05:02:14,156 INFO org.apache.hadoop.yarn.server.resourcemanager.scheduler.capacity.CapacityScheduler: Application attempt appattempt_1587939431661_0002_000002 released container container_1587939431661_0002_02_000001 on node: host: shivansh18-VirtualBox:45511 #containers=0 available=8192 used=0 with event: FINISHED
2020-04-27 05:02:14,156 INFO org.apache.hadoop.yarn.server.resourcemanager.security.AMRMTokenSecretManager: Application finished, removing password for appattempt_1587939431661_0002_000002
2020-04-27 05:02:14,157 INFO org.apache.hadoop.yarn.server.resourcemanager.rmapp.attempt.RMAppAttemptImpl: appattempt_1587939431661_0002_000002 State change from FINAL_SAVING to FAILED
2020-04-27 05:02:14,157 INFO org.apache.hadoop.yarn.server.resourcemanager.rmapp.RMAppImpl: The number of failed attempts is 2. The max attempts is 2
2020-04-27 05:02:14,172 INFO org.apache.hadoop.yarn.server.resourcemanager.rmapp.RMAppImpl: Updating application application_1587939431661_0002 with final state: FAILED
2020-04-27 05:02:14,205 INFO org.apache.hadoop.yarn.server.resourcemanager.rmapp.RMAppImpl: application_1587939431661_0002 State change from ACCEPTED to FINAL_SAVING
2020-04-27 05:02:14,205 INFO org.apache.hadoop.yarn.server.resourcemanager.scheduler.capacity.CapacityScheduler: Application Attempt appattempt_1587939431661_0002_000002 is done. finalState=FAILED
2020-04-27 05:02:14,205 INFO org.apache.hadoop.yarn.server.resourcemanager.recovery.RMStateStore: Updating info for app: application_1587939431661_0002
2020-04-27 05:02:14,205 INFO org.apache.hadoop.yarn.server.resourcemanager.scheduler.AppSchedulingInfo: Application application_1587939431661_0002 requests cleared
2020-04-27 05:02:14,205 INFO org.apache.hadoop.yarn.server.resourcemanager.scheduler.capacity.LeafQueue: Application removed - appId: application_1587939431661_0002 user: root queue: default #user-pending-applications: 0 #user-active-applications: 0 #queue-pending-applications: 0 #queue-active-applications: 0
2020-04-27 05:02:14,205 INFO org.apache.hadoop.yarn.server.resourcemanager.rmapp.RMAppImpl: Application application_1587939431661_0002 failed 2 times due to AM Container for appattempt_1587939431661_0002_000002 exited with  exitCode: -103
For more detailed output, check application tracking page:http://shivansh18-VirtualBox:8088/proxy/application_1587939431661_0002/Then, click on links to logs of each attempt.
Diagnostics: Container [pid=22324,containerID=container_1587939431661_0002_02_000001] is running beyond virtual memory limits. Current usage: 90.3 MB of 1 GB physical memory used; 2.3 GB of 2.1 GB virtual memory used. Killing container.
Dump of the process-tree for container_1587939431661_0002_02_000001 :
	|- PID PPID PGRPID SESSID CMD_NAME USER_MODE_TIME(MILLIS) SYSTEM_TIME(MILLIS) VMEM_USAGE(BYTES) RSSMEM_USAGE(PAGES) FULL_CMD_LINE

Container killed on request. Exit code is 143
Container exited with a non-zero exit code 143
Failing this attempt. Failing the application.
2020-04-27 05:02:14,211 INFO org.apache.hadoop.yarn.server.resourcemanager.rmapp.RMAppImpl: application_1587939431661_0002 State change from FINAL_SAVING to FAILED
2020-04-27 05:02:14,211 INFO org.apache.hadoop.yarn.server.resourcemanager.scheduler.capacity.ParentQueue: Application removed - appId: application_1587939431661_0002 user: root leaf-queue of parent: root #applications: 0
2020-04-27 05:02:14,215 WARN org.apache.hadoop.yarn.server.resourcemanager.RMAuditLogger: USER=root	OPERATION=Application Finished - Failed	TARGET=RMAppManager	RESULT=FAILURE	DESCRIPTION=App failed with state: FAILED	PERMISSIONS=Application application_1587939431661_0002 failed 2 times due to AM Container for appattempt_1587939431661_0002_000002 exited with  exitCode: -103
For more detailed output, check application tracking page:http://shivansh18-VirtualBox:8088/proxy/application_1587939431661_0002/Then, click on links to logs of each attempt.
Diagnostics: Container [pid=22324,containerID=container_1587939431661_0002_02_000001] is running beyond virtual memory limits. Current usage: 90.3 MB of 1 GB physical memory used; 2.3 GB of 2.1 GB virtual memory used. Killing container.
Dump of the process-tree for container_1587939431661_0002_02_000001 :
	|- PID PPID PGRPID SESSID CMD_NAME USER_MODE_TIME(MILLIS) SYSTEM_TIME(MILLIS) VMEM_USAGE(BYTES) RSSMEM_USAGE(PAGES) FULL_CMD_LINE

Container killed on request. Exit code is 143
Container exited with a non-zero exit code 143
Failing this attempt. Failing the application.	APPID=application_1587939431661_0002
2020-04-27 05:02:14,222 INFO org.apache.hadoop.yarn.server.resourcemanager.RMAppManager$ApplicationSummary: appId=application_1587939431661_0002,name=twitter-parser_1,user=root,queue=default,state=FAILED,trackingUrl=http://shivansh18-VirtualBox:8088/cluster/app/application_1587939431661_0002,appMasterHost=N/A,startTime=1587943904752,finishTime=1587943934172,finalStatus=FAILED
